Workbook
Name UPDATE: 'Data Sheet'!$E$1

Sheet Profit & Loss
A1: ='Data Sheet'!B1 -> BRITANNIA INDUSTRIES LTD | H1: =UPDATE | M1: SCREENER.IN
A3: Narration | B3: ='Data Sheet'!B16 -> 42825 | C3: ='Data Sheet'!C16 -> 43190 | D3: ='Data Sheet'!D16 -> 43555 | E3: ='Data Sheet'!E16 -> 43921 | F3: ='Data Sheet'!F16 -> 44286 | G3: ='Data Sheet'!G16 -> 44651 | H3: ='Data Sheet'!H16 -> 45016 | I3: ='Data Sheet'!I16 -> 45382 | ... K3: ='Data Sheet'!K16 -> 46112 | L3: Trailing | M3: Best Case | N3: Worst Case
A4: Sales | B4: ='Data Sheet'!B17 -> 9054.09 | C4: ='Data Sheet'!C17 -> 9913.99 | D4: ='Data Sheet'!D17 -> 11054.67 | E4: ='Data Sheet'!E17 -> 11599.55 | F4: ='Data Sheet'!F17 -> 13136.14 | G4: ='Data Sheet'!G17 -> 14136.26 | H4: ='Data Sheet'!H17 -> 16300.55 | I4: ='Data Sheet'!I17 -> 16769.27 | ... K4: ='Data Sheet'!K17 -> 19151.59 | L4: =SUM(Quarters!H4:K4) -> 19529.34 | M4: =$K4+M23*K4 -> 20441.963 | N4: =$K4+N23*L4 -> 20229.582
A5: Expenses | B5: =SUM('Data Sheet'!B18,'Data Sheet'!B20:B24, -1*'Data Sheet'!B19) -> 7775.91 | C5: =SUM('Data Sheet'!C18,'Data Sheet'!C20:C24, -1*'Data Sheet'!C19) -> 8412.52 | D5: =SUM('Data Sheet'!D18,'Data Sheet'!D20:D24, -1*'Data Sheet'!D19) -> 9322.22 | E5: =SUM('Data Sheet'!E18,'Data Sheet'!E20:E24, -1*'Data Sheet'!E19) -> 9756.37 | F5: =SUM('Data Sheet'!F18,'Data Sheet'!F20:F24, -1*'Data Sheet'!F19) -> 10626.85 | G5: =SUM('Data Sheet'!G18,'Data Sheet'!G20:G24, -1*'Data Sheet'!G19) -> 11934.95 | H5: =SUM('Data Sheet'!H18,'Data Sheet'!H20:H24, -1*'Data Sheet'!H19) -> 13469.64 | I5: =SUM('Data Sheet'!I18,'Data Sheet'!I20:I24, -1*'Data Sheet'!I19) -> 13602.62 | ... K5: =SUM('Data Sheet'!K18,'Data Sheet'!K20:K24, -1*'Data Sheet'!K19) -> 15637.25 | L5: =SUM(Quarters!H5:K5) -> 15928.88 | M5: =M4-M6 -> 16673.251 | N5: =N4-N6 -> 16773.94
A6: Operating Profit | B6: =B4-B5 -> 1278.18 | C6: =C4-C5 -> 1501.47 | D6: =D4-D5 -> 1732.45 | E6: =E4-E5 -> 1843.18 | F6: =F4-F5 -> 2509.29 | G6: =G4-G5 -> 2201.31 | H6: =H4-H5 -> 2830.91 | I6: =I4-I5 -> 3166.65 | ... K6: =K4-K5 -> 3514.34 | L6: =SUM(Quarters!H6:K6) -> 3600.46 | M6: =M4*M24 -> 3768.7127 | N6: =N4*N24 -> 3455.6417
A7: Other Income | B7: ='Data Sheet'!B25 -> 150.54 | C7: ='Data Sheet'!C25 -> 166.37 | D7: ='Data Sheet'!D25 -> 206.45 | E7: ='Data Sheet'!E25 -> 262.83 | F7: ='Data Sheet'!F25 -> 313.07 | G7: ='Data Sheet'!G25 -> 221.85 | H7: ='Data Sheet'!H25 -> 596.87 | I7: ='Data Sheet'!I25 -> 211.28 | ... K7: ='Data Sheet'!K25 -> 224.03 | L7: =SUM(Quarters!H7:K7) -> 228.43 | M7: 0 | N7: 0
A8: Depreciation | B8: ='Data Sheet'!B26 -> 119.27 | C8: ='Data Sheet'!C26 -> 142.07 | D8: ='Data Sheet'!D26 -> 161.88 | E8: ='Data Sheet'!E26 -> 184.81 | F8: ='Data Sheet'!F26 -> 197.85 | G8: ='Data Sheet'!G26 -> 200.54 | H8: ='Data Sheet'!H26 -> 225.91 | I8: ='Data Sheet'!I26 -> 300.46 | ... K8: ='Data Sheet'!K26 -> 336.83 | L8: =SUM(Quarters!H8:K8) -> 334.3 | M8: =+$L8 -> 334.3 | N8: =+$L8 -> 334.3
A9: Interest | B9: ='Data Sheet'!B27 -> 5.45 | C9: ='Data Sheet'!C27 -> 7.59 | D9: ='Data Sheet'!D27 -> 9.09 | E9: ='Data Sheet'!E27 -> 76.9 | F9: ='Data Sheet'!F27 -> 110.9 | G9: ='Data Sheet'!G27 -> 144.29 | H9: ='Data Sheet'!H27 -> 169.1 | I9: ='Data Sheet'!I27 -> 164 | ... K9: ='Data Sheet'!K27 -> 112.76 | L9: =SUM(Quarters!H9:K9) -> 109.48 | M9: =+$L9 -> 109.48 | N9: =+$L9 -> 109.48
A10: Profit before tax | B10: ='Data Sheet'!B28 -> 1304 | C10: ='Data Sheet'!C28 -> 1518.18 | D10: ='Data Sheet'!D28 -> 1767.93 | E10: ='Data Sheet'!E28 -> 1844.3 | F10: ='Data Sheet'!F28 -> 2513.61 | G10: ='Data Sheet'!G28 -> 2078.33 | H10: ='Data Sheet'!H28 -> 3032.77 | I10: ='Data Sheet'!I28 -> 2913.47 | ... K10: ='Data Sheet'!K28 -> 3288.78 | L10: =SUM(Quarters!H10:K10) -> 3385.11 | M10: =M6+M7-SUM(M8:M9) -> 3324.9327 | N10: =N6+N7-SUM(N8:N9) -> 3011.8617
A11: Tax | B11: ='Data Sheet'!B29 -> 419.67 | C11: ='Data Sheet'!C29 -> 514.22 | D11: ='Data Sheet'!D29 -> 612.47 | E11: ='Data Sheet'!E29 -> 450.7 | F11: ='Data Sheet'!F29 -> 663.02 | G11: ='Data Sheet'!G29 -> 562.35 | H11: ='Data Sheet'!H29 -> 716.45 | I11: ='Data Sheet'!I29 -> 779.25 | ... K11: ='Data Sheet'!K29 -> 751.77 | L11: =SUM(Quarters!H11:K11) -> 774.85 | M11: =IF($L10>0,$L11/$L10,0) -> 0.2288995 | N11: =IF($L10>0,$L11/$L10,0) -> 0.2288995
A12: Net profit | B12: ='Data Sheet'!B30 -> 884.47 | C12: ='Data Sheet'!C30 -> 1004.23 | D12: ='Data Sheet'!D30 -> 1159.12 | E12: ='Data Sheet'!E30 -> 1402.63 | F12: ='Data Sheet'!F30 -> 1863.9 | G12: ='Data Sheet'!G30 -> 1524.82 | H12: ='Data Sheet'!H30 -> 2321.77 | I12: ='Data Sheet'!I30 -> 2139.81 | ... K12: ='Data Sheet'!K30 -> 2533.49 | L12: =SUM(Quarters!H12:K12) -> 2604.12 | M12: =M10-M11*M10 -> 2563.8572 | N12: =N10-N11*N10 -> 2322.4481
A13: EPS | B13: =IF('Data Sheet'!B93>0,B12/'Data Sheet'!B93,0) -> 36.852917 | C13: =IF('Data Sheet'!C93>0,C12/'Data Sheet'!C93,0) -> 41.825489 | D13: =IF('Data Sheet'!D93>0,D12/'Data Sheet'!D93,0) -> 48.236371 | E13: =IF('Data Sheet'!E93>0,E12/'Data Sheet'!E93,0) -> 58.321414 | F13: =IF('Data Sheet'!F93>0,F12/'Data Sheet'!F93,0) -> 77.372354 | G13: =IF('Data Sheet'!G93>0,G12/'Data Sheet'!G93,0) -> 63.296804 | H13: =IF('Data Sheet'!H93>0,H12/'Data Sheet'!H93,0) -> 96.378995 | I13: =IF('Data Sheet'!I93>0,I12/'Data Sheet'!I93,0) -> 88.825654 | ... K13: =IF('Data Sheet'!K93>0,K12/'Data Sheet'!K93,0) -> 105.1677 | L13: =IF('Data Sheet'!$B6>0,'Profit & Loss'!L12/'Data Sheet'!$B6,0) -> 108.11391 | M13: =IF('Data Sheet'!$B6>0,'Profit & Loss'!M12/'Data Sheet'!$B6,0) -> 106.44234 | N13: =IF('Data Sheet'!$B6>0,'Profit & Loss'!N12/'Data Sheet'!$B6,0) -> 96.419878
A14: Price to earning | B14: =IF(B15>0,B15/B13,"") -> 45.776567 | C14: =IF(C15>0,C15/C13,"") -> 59.420703 | D14: =IF(D15>0,D15/D13,"") -> 63.966255 | E14: =IF(E15>0,E15/E13,"") -> 46.105707 | F14: =IF(F15>0,F15/F13,"") -> 46.852006 | G14: =IF(G15>0,G15/G13,"") -> 50.656586 | H14: =IF(H15>0,H15/H13,"") -> 44.845352 | I14: =IF(I15>0,I15/I13,"") -> 55.290896 | ... K14: =IF(K15>0,K15/K13,"") -> 51.56526 | L14: =IF(L13>0,L15/L13,0) -> 46.340015 | M14: =M25 -> 51.945745 | N14: =N25 -> 46.340015
A15: Price | B15: ='Data Sheet'!B90 -> 1687 | C15: ='Data Sheet'!C90 -> 2485.3 | D15: ='Data Sheet'!D90 -> 3085.5 | E15: ='Data Sheet'!E90 -> 2688.95 | F15: ='Data Sheet'!F90 -> 3625.05 | G15: ='Data Sheet'!G90 -> 3206.4 | H15: ='Data Sheet'!H90 -> 4322.15 | I15: ='Data Sheet'!I90 -> 4911.25 | ... K15: ='Data Sheet'!K90 -> 5423 | L15: ='Data Sheet'!B8 -> 5010 | M15: =M13*M14 -> 5529.2265 | N15: =N13*N14 -> 4468.0986
A16: OPM | B16: =B6/B4 -> 0.14117156 | C16: =C6/C4 -> 0.15144962 | D16: =D6/D4 -> 0.15671657 | E16: =E6/E4 -> 0.15890099 | F16: =F6/F4 -> 0.19102187 | G16: =G6/G4 -> 0.15572082 | H16: =H6/H4 -> 0.1736696 | I16: =I6/I4 -> 0.18883648 | ... N16: =N6/N4 -> 0.17082122
A17: RATIOS:
A18: Dividend Payout | B18: =IF('Data Sheet'!B30>0, 'Data Sheet'!B31/'Data Sheet'!B30, 0) -> 0.29848384 | C18: =IF('Data Sheet'!C30>0, 'Data Sheet'!C31/'Data Sheet'!C30, 0) -> 0.29885584 | D18: =IF('Data Sheet'!D30>0, 'Data Sheet'!D31/'Data Sheet'!D30, 0) -> 0.31096867 | E18: =IF('Data Sheet'!E30>0, 'Data Sheet'!E31/'Data Sheet'!E30, 0) -> 0.60012263 | F18: =IF('Data Sheet'!F30>0, 'Data Sheet'!F31/'Data Sheet'!F30, 0) -> 2.0356135 | G18: =IF('Data Sheet'!G30>0, 'Data Sheet'!G31/'Data Sheet'!G30, 0) -> 0.89261683 | H18: =IF('Data Sheet'!H30>0, 'Data Sheet'!H31/'Data Sheet'!H30, 0) -> 0.74705074 | I18: =IF('Data Sheet'!I30>0, 'Data Sheet'!I31/'Data Sheet'!I30, 0) -> 0.82746599 | ... K18: =IF('Data Sheet'!K30>0, 'Data Sheet'!K31/'Data Sheet'!K30, 0) -> 0.86052836
A19: OPM | B19: =IF(B6>0,B6/B4,0) -> 0.14117156 | C19: =IF(C6>0,C6/C4,0) -> 0.15144962 | D19: =IF(D6>0,D6/D4,0) -> 0.15671657 | E19: =IF(E6>0,E6/E4,0) -> 0.15890099 | F19: =IF(F6>0,F6/F4,0) -> 0.19102187 | G19: =IF(G6>0,G6/G4,0) -> 0.15572082 | H19: =IF(H6>0,H6/H4,0) -> 0.1736696 | I19: =IF(I6>0,I6/I4,0) -> 0.18883648 | ... L19: =IF(L6>0,L6/L4,0) -> 0.18436158
G22: TRENDS: | H22: 10 YEARS | I22: 7 YEARS | J22: 5 YEARS | K22: 3 YEARS | L22: RECENT | M22: BEST | N22: WORST
G23: Sales Growth | H23: =IF(B4=0,"",POWER($K4/B4,1/9)-1) -> 0.086803715 | I23: =IF(D4=0,"",POWER($K4/D4,1/7)-1) -> 0.08166842 | J23: =IF(F4=0,"",POWER($K4/F4,1/5)-1) -> 0.078319387 | K23: =IF(H4=0,"",POWER($K4/H4, 1/3)-1) -> 0.055198566 | L23: =IF(ISERROR(MAX(IF(J4=0,"",(K4-J4)/J4),IF(K4=0,"",(L4-K4)/K4))),"",MAX(IF(J4=0,"",(K4-J4)/J4),IF(K4=0,"",(L4-K4)/K4))) -> 0.067376817 | M23: =MAX(K23:L23) -> 0.067376817 | N23: =MIN(H23:L23) -> 0.055198566
G24: OPM | H24: =IF(SUM(B4:$K$4)=0,"",SUMPRODUCT(B19:$K$19,B4:$K$4)/SUM(B4:$K$4)) -> 0.17082122 | I24: =IF(SUM(E4:$K$4)=0,"",SUMPRODUCT(E19:$K$19,E4:$K$4)/SUM(E4:$K$4)) -> 0.1764746 | J24: =IF(SUM(G4:$K$4)=0,"",SUMPRODUCT(G19:$K$19,G4:$K$4)/SUM(G4:$K$4)) -> 0.17662586 | K24: =IF(SUM(I4:$K$4)=0, "", SUMPRODUCT(I19:$K$19,I4:$K$4)/SUM(I4:$K$4)) -> 0.18300694 | L24: =L19 -> 0.18436158 | M24: =MAX(K24:L24) -> 0.18436158 | N24: =MIN(H24:L24) -> 0.17082122
G25: Price to Earning | H25: =IF(ISERROR(AVERAGEIF(B14:$L14,">0")),"",AVERAGEIF(B14:$L14,">0")) -> 51.40056 | I25: =IF(ISERROR(AVERAGEIF(E14:$L14,">0")),"",AVERAGEIF(E14:$L14,">0")) -> 49.530329 | J25: =IF(ISERROR(AVERAGEIF(G14:$L14,">0")),"",AVERAGEIF(G14:$L14,">0")) -> 50.547487 | K25: =IF(ISERROR(AVERAGEIF(I14:$L14,">0")),"",AVERAGEIF(I14:$L14,">0")) -> 51.945745 | L25: =L14 -> 46.340015 | M25: =MAX(K25:L25) -> 51.945745 | N25: =MIN(H25:L25) -> 46.340015

Sheet Data Sheet
A1: COMPANY NAME | B1: BRITANNIA INDUSTRIES LTD | E1: =IF(B2<>B3, "A NEW VERSION OF THE WORKSHEET IS AVAILABLE", "")
A2: LATEST VERSION | B2: 2.1 | E2: PLEASE DO NOT MAKE ANY CHANGES TO THIS SHEET
A3: CURRENT VERSION | B3: 2.1
A5: META
A6: Number of shares | B6: =IF(B9>0, B9/B8, 0) -> 24.086818
A7: Face Value | B7: 1
A8: Current Price | B8: 5010
A9: Market Capitalization | B9: 120674.96
A15: PROFIT & LOSS
A16: Report Date | B16: 42825 | C16: 43190 | D16: 43555 | E16: 43921 | F16: 44286 | G16: 44651 | H16: 45016 | I16: 45382 | J16: 45747 | K16: 46112
A17: Sales | B17: 9054.09 | C17: 9913.99 | D17: 11054.67 | E17: 11599.55 | F17: 13136.14 | G17: 14136.26 | H17: 16300.55 | I17: 16769.27 | J17: 17942.67 | K17: 19151.59
A18: Raw Material Cost | B18: 5642.88 | C18: 6100.8 | D18: 6616.64 | E18: 6874.9 | F18: 7663.22 | G18: 8835.56 | H18: 9663.83 | I18: 9488.37 | J18: 10668.8 | K18: 11155.25
A19: Change in Inventory | B19: 54.2 | C19: -6.3 | D19: 55.18 | E19: -52.57 | F19: 37.12 | G19: 75.26 | H19: 72.53 | I19: -3.66 | J19: 64.75 | K19: 22.37
A20: Power and Fuel | B20: 104.28 | C20: 128.83 | D20: 175.17 | E20: 177.7 | F20: 182.29 | G20: 217.68 | H20: 272.2 | I20: 327.25 | J20: 357.98 | K20: 342.87
A21: Other Mfr. Exp | B21: 509.93 | C21: 487.59 | D21: 621.32 | E21: 610.68 | F21: 672.21 | G21: 752.29 | H21: 893.75 | I21: 876.12 | J21: 954.03 | K21: 920.68
A22: Employee Cost | B22: 352.61 | C22: 401.6 | D22: 441.82 | E22: 486.69 | F22: 527.38 | G22: 542.26 | H22: 658.38 | I22: 708.7 | J22: 704.59 | K22: 823.8
A23: Selling and admin | B23: 915.01 | C23: 953.48 | D23: 1107.49 | E23: 1125.23 | F23: 1163.82 | G23: 1187.32 | H23: 1473.86 | I23: 1525.52 | J23: 1360 | K23: 1575.23
A24: Other Expenses | B24: 305.4 | C24: 333.92 | D24: 414.96 | E24: 428.6 | F24: 455.05 | G24: 475.1 | H24: 580.15 | I24: 673 | J24: 785.61 | K24: 841.79
A25: Other Income | B25: 150.54 | C25: 166.37 | D25: 206.45 | E25: 262.83 | F25: 313.07 | G25: 221.85 | H25: 596.87 | I25: 211.28 | J25: 202.3 | K25: 224.03
A26: Depreciation | B26: 119.27 | C26: 142.07 | D26: 161.88 | E26: 184.81 | F26: 197.85 | G26: 200.54 | H26: 225.91 | I26: 300.46 | J26: 313.34 | K26: 336.83
A27: Interest | B27: 5.45 | C27: 7.59 | D27: 9.09 | E27: 76.9 | F27: 110.9 | G27: 144.29 | H27: 169.1 | I27: 164 | J27: 138.8 | K27: 112.76
... A31: Dividend Amount | B31: 264 | C31: 300.12 | D31: 360.45 | E31: 841.75 | F31: 3794.18 | G31: 1361.08 | H31: 1734.48 | I31: 1770.62 | J31: 1806.75 | K31: 2180.14
A40: Quarters
A41: Report Date | B41: 45382 | C41: 45473 | D41: 45565 | E41: 45657 | F41: 45747 | G41: 45838 | H41: 45930 | I41: 46022 | J41: 46112 | K41: 46203
A42: Sales | B42: 4069.36 | C42: 4250.29 | D42: 4667.57 | E42: 4592.61 | F42: 4432.19 | G42: 4622.22 | H42: 4840.63 | I42: 4969.82 | J42: 4718.92 | K42: 4999.97
A43: Expenses | B43: 3285.71 | C43: 3497.28 | D43: 3887.56 | E43: 3749.75 | F43: 3631.67 | G43: 3870.02 | H43: 3889.39 | I43: 3992.49 | J43: 3885.35 | K43: 4161.65
A44: Other Income | B44: 57.34 | C44: 30.97 | D44: 45.85 | E44: 62.46 | F44: 63.02 | G44: 57.01 | H44: 52.11 | I44: 59.46 | J44: 55.45 | K44: 61.41
A45: Depreciation | B45: 79.93 | C45: 73.93 | D45: 76.07 | E45: 82.38 | F45: 80.96 | G45: 82.04 | H45: 85.05 | I45: 84.51 | J45: 85.23 | K45: 79.51
A46: Interest | B46: 26.44 | C46: 28.95 | D46: 34.64 | E46: 44.56 | F46: 30.65 | G46: 26.15 | H46: 34.68 | I46: 33.25 | J46: 18.68 | K46: 22.87
A47: Profit before tax | B47: 734.62 | C47: 681.1 | D47: 715.15 | E47: 778.38 | F47: 751.93 | G47: 701.02 | H47: 883.62 | I47: 919.03 | J47: 785.11 | K47: 797.35
A48: Tax | B48: 198.01 | C48: 176.22 | D48: 183.6 | E48: 196.08 | F48: 192.8 | G48: 180.89 | H48: 228.56 | I48: 236.89 | J48: 105.43 | K48: 203.97
A49: Net profit | B49: 538.28 | C49: 505.64 | D49: 531.45 | E49: 581.69 | F49: 559.95 | G49: 520.72 | H49: 654.47 | I49: 679.96 | J49: 678.34 | K49: 591.35
A50: Operating Profit | B50: 783.65 | C50: 753.01 | D50: 780.01 | E50: 842.86 | F50: 800.52 | G50: 752.2 | H50: 951.24 | I50: 977.33 | J50: 833.57 | K50: 838.32
A55: BALANCE SHEET
A56: Report Date | B56: 42825 | C56: 43190 | D56: 43555 | E56: 43921 | F56: 44286 | G56: 44651 | H56: 45016 | I56: 45382 | J56: 45747 | K56: 46112
A57: Equity Share Capital | B57: 24 | C57: 24.01 | D57: 24.03 | E57: 24.05 | F57: 24.09 | G57: 24.09 | H57: 24.09 | I57: 24.09 | J57: 24.09 | K57: 24.09
A58: Reserves | B58: 2672.42 | C58: 3382.22 | D58: 4229.22 | E58: 4378.78 | F58: 3523.57 | G58: 2534.01 | H58: 3510.18 | I58: 3917.43 | J58: 4331.63 | K58: 5082.47
A59: Borrowings | B59: 124.56 | C59: 200.7 | D59: 156.02 | E59: 1537.59 | F59: 2106.94 | G59: 2481.2 | H59: 2997.37 | I59: 2064.96 | J59: 1246.51 | K59: 1380.28
A60: Other Liabilities | B60: 1287.82 | C60: 1580.99 | D60: 1828.68 | E60: 1889.12 | F60: 2345.49 | G60: 2487.3 | H60: 2819.21 | I60: 3065.02 | J60: 3234.52 | K60: 3243.48
A61: Total | B61: 4108.8 | C61: 5187.92 | D61: 6237.95 | E61: 7829.54 | F61: 8000.09 | G61: 7526.6 | H61: 9350.85 | I61: 9071.5 | J61: 8836.75 | K61: 9730.32
...

Sheet Quarters
A1: ='Profit & Loss'!A1 -> BRITANNIA INDUSTRIES LTD | E1: =UPDATE | J1: SCREENER.IN
A3: Narration | B3: ='Data Sheet'!B41 -> 45382 | C3: ='Data Sheet'!C41 -> 45473 | D3: ='Data Sheet'!D41 -> 45565 | E3: ='Data Sheet'!E41 -> 45657 | F3: ='Data Sheet'!F41 -> 45747 | G3: ='Data Sheet'!G41 -> 45838 | H3: ='Data Sheet'!H41 -> 45930 | I3: ='Data Sheet'!I41 -> 46022 | ... K3: ='Data Sheet'!K41 -> 46203
A4: Sales | B4: ='Data Sheet'!B42 -> 4069.36 | C4: ='Data Sheet'!C42 -> 4250.29 | D4: ='Data Sheet'!D42 -> 4667.57 | E4: ='Data Sheet'!E42 -> 4592.61 | F4: ='Data Sheet'!F42 -> 4432.19 | G4: ='Data Sheet'!G42 -> 4622.22 | H4: ='Data Sheet'!H42 -> 4840.63 | I4: ='Data Sheet'!I42 -> 4969.82 | ... K4: ='Data Sheet'!K42 -> 4999.97
A5: Expenses | B5: ='Data Sheet'!B43 -> 3285.71 | C5: ='Data Sheet'!C43 -> 3497.28 | D5: ='Data Sheet'!D43 -> 3887.56 | E5: ='Data Sheet'!E43 -> 3749.75 | F5: ='Data Sheet'!F43 -> 3631.67 | G5: ='Data Sheet'!G43 -> 3870.02 | H5: ='Data Sheet'!H43 -> 3889.39 | I5: ='Data Sheet'!I43 -> 3992.49 | ... K5: ='Data Sheet'!K43 -> 4161.65
A6: Operating Profit | B6: ='Data Sheet'!B50 -> 783.65 | C6: ='Data Sheet'!C50 -> 753.01 | D6: ='Data Sheet'!D50 -> 780.01 | E6: ='Data Sheet'!E50 -> 842.86 | F6: ='Data Sheet'!F50 -> 800.52 | G6: ='Data Sheet'!G50 -> 752.2 | H6: ='Data Sheet'!H50 -> 951.24 | I6: ='Data Sheet'!I50 -> 977.33 | ... K6: ='Data Sheet'!K50 -> 838.32
A7: Other Income | B7: ='Data Sheet'!B44 -> 57.34 | C7: ='Data Sheet'!C44 -> 30.97 | D7: ='Data Sheet'!D44 -> 45.85 | E7: ='Data Sheet'!E44 -> 62.46 | F7: ='Data Sheet'!F44 -> 63.02 | G7: ='Data Sheet'!G44 -> 57.01 | H7: ='Data Sheet'!H44 -> 52.11 | I7: ='Data Sheet'!I44 -> 59.46 | ... K7: ='Data Sheet'!K44 -> 61.41
A8: Depreciation | B8: ='Data Sheet'!B45 -> 79.93 | C8: ='Data Sheet'!C45 -> 73.93 | D8: ='Data Sheet'!D45 -> 76.07 | E8: ='Data Sheet'!E45 -> 82.38 | F8: ='Data Sheet'!F45 -> 80.96 | G8: ='Data Sheet'!G45 -> 82.04 | H8: ='Data Sheet'!H45 -> 85.05 | I8: ='Data Sheet'!I45 -> 84.51 | ... K8: ='Data Sheet'!K45 -> 79.51
A9: Interest | B9: ='Data Sheet'!B46 -> 26.44 | C9: ='Data Sheet'!C46 -> 28.95 | D9: ='Data Sheet'!D46 -> 34.64 | E9: ='Data Sheet'!E46 -> 44.56 | F9: ='Data Sheet'!F46 -> 30.65 | G9: ='Data Sheet'!G46 -> 26.15 | H9: ='Data Sheet'!H46 -> 34.68 | I9: ='Data Sheet'!I46 -> 33.25 | ... K9: ='Data Sheet'!K46 -> 22.87
A10: Profit before tax | B10: ='Data Sheet'!B47 -> 734.62 | C10: ='Data Sheet'!C47 -> 681.1 | D10: ='Data Sheet'!D47 -> 715.15 | E10: ='Data Sheet'!E47 -> 778.38 | F10: ='Data Sheet'!F47 -> 751.93 | G10: ='Data Sheet'!G47 -> 701.02 | H10: ='Data Sheet'!H47 -> 883.62 | I10: ='Data Sheet'!I47 -> 919.03 | ... K10: ='Data Sheet'!K47 -> 797.35
A11: Tax | B11: ='Data Sheet'!B48 -> 198.01 | C11: ='Data Sheet'!C48 -> 176.22 | D11: ='Data Sheet'!D48 -> 183.6 | E11: ='Data Sheet'!E48 -> 196.08 | F11: ='Data Sheet'!F48 -> 192.8 | G11: ='Data Sheet'!G48 -> 180.89 | H11: ='Data Sheet'!H48 -> 228.56 | I11: ='Data Sheet'!I48 -> 236.89 | ... K11: ='Data Sheet'!K48 -> 203.97
A12: Net profit | B12: ='Data Sheet'!B49 -> 538.28 | C12: ='Data Sheet'!C49 -> 505.64 | D12: ='Data Sheet'!D49 -> 531.45 | E12: ='Data Sheet'!E49 -> 581.69 | F12: ='Data Sheet'!F49 -> 559.95 | G12: ='Data Sheet'!G49 -> 520.72 | H12: ='Data Sheet'!H49 -> 654.47 | I12: ='Data Sheet'!I49 -> 679.96 | ... K12: ='Data Sheet'!K49 -> 591.35
A14: OPM | B14: =IF(B4>0,B6/B4,"") -> 0.19257328 | C14: =IF(C4>0,C6/C4,"") -> 0.17716673 | D14: =IF(D4>0,D6/D4,"") -> 0.16711265 | E14: =IF(E4>0,E6/E4,"") -> 0.18352527 | F14: =IF(F4>0,F6/F4,"") -> 0.180615 | G14: =IF(G4>0,G6/G4,"") -> 0.16273566 | H14: =IF(H4>0,H6/H4,"") -> 0.19651161 | I14: =IF(I4>0,I6/I4,"") -> 0.196653 | ... K14: =IF(K4>0,K6/K4,"") -> 0.16766501

Sheet Dashboard
C7: =
J10: Select Metric : | L10: Expenses
B31: Driver 1 : Margin Expansion Dynamics | G31: Driver 2 : Quarterly Variance Drivers | L31: Driver 3 :Stretegic Outlook & Capex
B32: EBITDA Margin : Reached 18.35% in FY 2026 (+65bps expansion). Input Costs: Palm oil and flour price stabilization reduced COGS to 58.2% of sales. Efficiency: Factory automation offset employee cost increases. | G32: Q3 Peak Performance: Operating Profit surged +22 % YoY during festive demand. Volume Growth: Urban retail distribution expanded by +8.4%. bAD Spend: Marketing spend held steady at 4.1% of revenue. | L32: Cash Operations : CFO of Rs.2,611.60 Cr covers FY2026 Capex (Rs.640 Cr) by 4.08x. Free Cash Flow: Reached record Rs.1,971.60 Cr. FY2027 Projection : Revenue projected at Rs.20,442.00 Cr (+6.7% YoY)

Sheet Model_Data
A1: Narration | B1: Quarter | C1: Amount
A2: Sales | B2: Mar-24 | C2: 4069.36
A3: Sales | B3: Jun-24 | C3: 4250.29
A4: Sales | B4: Sep-24 | C4: 4667.57
A5: Sales | B5: Dec-24 | C5: 4592.61 | E5: Sum of Amount | F5: Column Labels
A6: Sales | B6: Mar-25 | C6: 4432.19 | E6: Row Labels | F6: Operating Profit | G6: Sales | H6: Grand Total
A7: Sales | B7: Jun-25 | C7: 4622.22 | E7: Mar-24 | F7: 783.65 | G7: 4069.36 | H7: 4853.01 | L7: ='Profit & Loss'!K6 -> 3514.34 | N7: Metric | O7: ='Cash Flow'!G3 -> 44651 | P7: ='Cash Flow'!H3 -> 45016 | Q7: ='Cash Flow'!I3 -> 45382 | R7: ='Cash Flow'!J3 -> 45747 | S7: ='Cash Flow'!K3 -> 46112
A8: Sales | B8: Sep-25 | C8: 4840.63 | E8: Jun-24 | F8: 753.01 | G8: 4250.29 | H8: 5003.3 | L8: ='Profit & Loss'!K4/'Profit & Loss'!J4-1 -> 0.067376817 | N8: Operating Cash flow (Cr) | O8: ='Cash Flow'!G4 -> 1299.52 | P8: ='Cash Flow'!H4 -> 2526.21 | Q8: ='Cash Flow'!I4 -> 2572.98 | R8: ='Cash Flow'!J4 -> 2490.62 | S8: ='Cash Flow'!K4 -> 2611.6
A9: Sales | B9: Dec-25 | C9: 4969.82 | E9: Sep-24 | F9: 780.01 | G9: 4667.57 | H9: 5447.58 | L9: ='Profit & Loss'!K6/'Profit & Loss'!K4 -> 0.18350121 | N9: Investing Cash flow (Cr) | O9: ='Cash Flow'!G5 -> 914.19 | P9: ='Cash Flow'!H5 -> -1507 | Q9: ='Cash Flow'!I5 -> 485.44 | R9: ='Cash Flow'!J5 -> 69.07 | S9: ='Cash Flow'!K5 -> -741.38
A10: Sales | B10: Mar-26 | C10: 4718.92 | E10: Dec-24 | F10: 842.86 | G10: 4592.61 | H10: 5435.47 | L10: ='Profit & Loss'!K12 -> 2533.49
A11: Sales | B11: Jun-26 | C11: 4999.97 | E11: Mar-25 | F11: 800.52 | G11: 4432.19 | H11: 5232.71 | L11: ='Profit & Loss'!K12/'Profit & Loss'!K4 -> 0.13228614
A12: Expenses | B12: Mar-24 | C12: 3285.71 | E12: Jun-25 | F12: 752.2 | G12: 4622.22 | H12: 5374.42 | L12: ='Cash Flow'!K4 -> 2611.6
A13: Expenses | B13: Jun-24 | C13: 3497.28 | E13: Sep-25 | F13: 951.24 | G13: 4840.63 | H13: 5791.87 | L13: ='Cash Flow'!K4/'Profit & Loss'!K12 -> 1.030831
A14: Expenses | B14: Sep-24 | C14: 3887.56 | E14: Dec-25 | F14: 977.33 | G14: 4969.82 | H14: 5947.15 | L14: =Forecast!H2 -> 20441.963
A15: Expenses | B15: Dec-24 | C15: 3749.75 | E15: Mar-26 | F15: 833.57 | G15: 4718.92 | H15: 5552.49 | L15: =Forecast!H2/'Profit & Loss'!K4-1 -> 0.067376817
A16: Expenses | B16: Mar-25 | C16: 3631.67 | E16: Jun-26 | F16: 838.32 | G16: 4999.97 | H16: 5838.29
A17: Expenses | B17: Jun-25 | C17: 3870.02 | E17: Grand Total | F17: 8312.71 | G17: 46163.58 | H17: 54476.29
A18: Expenses | B18: Sep-25 | C18: 3889.39
A19: Expenses | B19: Dec-25 | C19: 3992.49
A20: Expenses | B20: Mar-26 | C20: 3885.35
A21: Expenses | B21: Jun-26 | C21: 4161.65
A22: Operating Profit | B22: Mar-24 | C22: 783.65
A23: Operating Profit | B23: Jun-24 | C23: 753.01
A24: Operating Profit | B24: Sep-24 | C24: 780.01
A25: Operating Profit | B25: Dec-24 | C25: 842.86
A26: Operating Profit | B26: Mar-25 | C26: 800.52
A27: Operating Profit | B27: Jun-25 | C27: 752.2
A28: Operating Profit | B28: Sep-25 | C28: 951.24
A29: Operating Profit | B29: Dec-25 | C29: 977.33
... A31: Operating Profit | B31: Jun-26 | C31: 838.32

Sheet Commentary
A1: TOP 4 VARIANCE DRIVERS (auto -ranked)
A3: Rank | B3: Line Item | C3: Quarter | D3: Variance % | E3: Flag | F3: Your Note( why) | G3: Your Note (Recommendation)
A4: 1 | B4: {=INDEX('Budget vs Actual'!$A$4:$A$21,MATCH(D4,ABS('Budget vs Actual'!$F$4:$F$21),0))} -> Operating Profit | C4: {=INDEX('Budget vs Actual'!$B$4:$B$21,MATCH(D4,ABS('Budget vs Actual'!$F$4:$F$21),0))} -> 45930 | D4: {=LARGE(ABS('Budget vs Actual'!$F$4:$F$21),1)} -> 0.21952283 | E4: {=INDEX('Budget vs Actual'!$G$4:$G$21,MATCH(D4,ABS('Budget vs Actual'!$F$4:$F$21),0))} -> Favourable | F4: Margin jumped ~290 bps YoY this quarter — driven by steady raw material costs plus tighter cost control, including a sharp cut in employee expenses and lower overheads. | G4: Lock in current cost discipline as a repeatable practice, not a one-off — track employee cost ratio and overhead ratio quarterly to catch slippage early.
A5: 2 | B5: {=INDEX('Budget vs Actual'!$A$4:$A$21,MATCH(D5,ABS('Budget vs Actual'!$F$4:$F$21),0))} -> Operating Profit | C5: {=INDEX('Budget vs Actual'!$B$4:$B$21,MATCH(D5,ABS('Budget vs Actual'!$F$4:$F$21),0))} -> 46022 | D5: {=LARGE(ABS('Budget vs Actual'!$F$4:$F$21),2)} -> 0.15954014 | E5: {=INDEX('Budget vs Actual'!$G$4:$G$21,MATCH(D5,ABS('Budget vs Actual'!$F$4:$F$21),0))} -> Favourable | F5: Revenue grew steady double-digit YoY, and margin held firm as commodity prices (palm oil, cocoa) eased slightly versus prior quarter, plus strong contribution from faster-growing adjacent categories (cakes, wafers, rusk). | G5: Keep watching commodity price trend — this was a tailwind, not guaranteed to repeat. Model a sensitivity case for input cost reversal.
A6: 3 | B6: {=INDEX('Budget vs Actual'!$A$4:$A$21,MATCH(D6,ABS('Budget vs Actual'!$F$4:$F$21),0))} -> Operating Profit | C6: {=INDEX('Budget vs Actual'!$B$4:$B$21,MATCH(D6,ABS('Budget vs Actual'!$F$4:$F$21),0))} -> 46203 | D6: {=LARGE(ABS('Budget vs Actual'!$F$4:$F$21),3)} -> 0.11449083 | E6: {=INDEX('Budget vs Actual'!$G$4:$G$21,MATCH(D6,ABS('Budget vs Actual'!$F$4:$F$21),0))} -> Favourable | F6: Continued benefit from raw material cost stabilization plus a formal cost-mitigation program the company started this quarter specifically to offset future inflation/input-cost risk. | G6: Favorable trend, but driver has shifted from "lucky easing" to "active program" — good sign for sustainability, worth flagging as a watch-item for durability in forecast assumptions.
A7: 4 | B7: {=INDEX('Budget vs Actual'!$A$4:$A$21,MATCH(D7,ABS('Budget vs Actual'!$F$4:$F$21),0))} -> Expenses | C7: {=INDEX('Budget vs Actual'!$B$4:$B$21,MATCH(D7,ABS('Budget vs Actual'!$F$4:$F$21),0))} -> 45838 | D7: {=LARGE(ABS('Budget vs Actual'!$F$4:$F$21),4)} -> 0.10657997 | E7: {=INDEX('Budget vs Actual'!$G$4:$G$21,MATCH(D7,ABS('Budget vs Actual'!$F$4:$F$21),0))} -> Unfavourable | F7: Revenue grew well this quarter (~9%), but expenses grew even faster — raw material cost inflation, higher packaging/distribution costs, and increased promotional spend all hit at once, while volume growth came in weaker than expected (only 2%). | G7: Flag as a quarter where spend grew ahead of volume — worth separating "temporary promo push" from "structural cost creep" before budgeting next year's similar quarter.
U15: r

Sheet Trend
A1: SALES AND OPERATING PROFIT TREND - 10 QUARTERS

Sheet Budget vs Actual
A1: BUDGET VS ACTUAL (Dynamic) | L1: 6
A3: Line Item | B3: Quarter | C3: Budget (PY Qtr) | D3: Actual | E3: Variance | F3: Variance % | G3: Flag | J3: Quarter | K3: Budget | L3: Actual | M3: Varience | N3: Variance %
A4: =Quarters!$A$4 -> Sales | B4: {=TRANSPOSE(Quarters!F3:K3)} -> 45747 | C4: {=_xlfn.XLOOKUP(1,(Model_Data!A:A=$A4)*(Model_Data!B:B=TEXT(EDATE($B4,-12),"mmm-yy")),Model_Data!C:C)} -> 4069.36 | D4: {=_xlfn.XLOOKUP(1,(Model_Data!A:A=$A4)*(Model_Data!B:B=TEXT($B4,"mmm-yy")),Model_Data!C:C)} -> 4432.19 | E4: =D4-C4 -> 362.83 | F4: =E4/C4 -> 0.089161441 | G4: =IF(E4>0,"Favourable","Unfavourable") -> Favourable | J4: =B4 -> 45747 | K4: =IF(Dashboard!$L$10="Sales",C4,IF(Dashboard!$L$10="Expenses",C10,C16)) -> 3285.71 | L4: =IF(Dashboard!$L$10="Sales",D4,IF(Dashboard!$L$10="Expenses",D10,D16)) -> 3631.67 | M4: =MAX(K4,L4)+300 -> 3931.67 | N4: =L4/K4-1 -> 0.10529231
A5: =Quarters!$A$4 -> Sales | B5: 45838 | C5: {=_xlfn.XLOOKUP(1,(Model_Data!A:A=$A5)*(Model_Data!B:B=TEXT(EDATE($B5,-12),"mmm-yy")),Model_Data!C:C)} -> 4250.29 | D5: {=_xlfn.XLOOKUP(1,(Model_Data!A:A=$A5)*(Model_Data!B:B=TEXT($B5,"mmm-yy")),Model_Data!C:C)} -> 4622.22 | E5: =D5-C5 -> 371.93 | F5: =E5/C5 -> 0.08750697 | G5: =IF(E5>0,"Favourable","Unfavourable") -> Favourable | J5: =B5 -> 45838 | K5: =IF(Dashboard!$L$10="Sales",C5,IF(Dashboard!$L$10="Expenses",C11,C17)) -> 3497.28 | L5: =IF(Dashboard!$L$10="Sales",D5,IF(Dashboard!$L$10="Expenses",D11,D17)) -> 3870.02 | M5: =MAX(K5,L5)+300 -> 4170.02 | N5: =L5/K5-1 -> 0.10657997
A6: =Quarters!$A$4 -> Sales | B6: 45930 | C6: {=_xlfn.XLOOKUP(1,(Model_Data!A:A=$A6)*(Model_Data!B:B=TEXT(EDATE($B6,-12),"mmm-yy")),Model_Data!C:C)} -> 4667.57 | D6: {=_xlfn.XLOOKUP(1,(Model_Data!A:A=$A6)*(Model_Data!B:B=TEXT($B6,"mmm-yy")),Model_Data!C:C)} -> 4840.63 | E6: =D6-C6 -> 173.06 | F6: =E6/C6 -> 0.037077109 | G6: =IF(E6>0,"Favourable","Unfavourable") -> Favourable | J6: =B6 -> 45930 | K6: =IF(Dashboard!$L$10="Sales",C6,IF(Dashboard!$L$10="Expenses",C12,C18)) -> 3887.56 | L6: =IF(Dashboard!$L$10="Sales",D6,IF(Dashboard!$L$10="Expenses",D12,D18)) -> 3889.39 | M6: =MAX(K6,L6)+300 -> 4189.39 | N6: =L6/K6-1 -> 0.00047073228
A7: =Quarters!$A$4 -> Sales | B7: 46022 | C7: {=_xlfn.XLOOKUP(1,(Model_Data!A:A=$A7)*(Model_Data!B:B=TEXT(EDATE($B7,-12),"mmm-yy")),Model_Data!C:C)} -> 4592.61 | D7: {=_xlfn.XLOOKUP(1,(Model_Data!A:A=$A7)*(Model_Data!B:B=TEXT($B7,"mmm-yy")),Model_Data!C:C)} -> 4969.82 | E7: =D7-C7 -> 377.21 | F7: =E7/C7 -> 0.082134124 | G7: =IF(E7>0,"Favourable","Unfavourable") -> Favourable | J7: =B7 -> 46022 | K7: =IF(Dashboard!$L$10="Sales",C7,IF(Dashboard!$L$10="Expenses",C13,C19)) -> 3749.75 | L7: =IF(Dashboard!$L$10="Sales",D7,IF(Dashboard!$L$10="Expenses",D13,D19)) -> 3992.49 | M7: =MAX(K7,L7)+300 -> 4292.49 | N7: =L7/K7-1 -> 0.064734982
A8: =Quarters!$A$4 -> Sales | B8: 46112 | C8: {=_xlfn.XLOOKUP(1,(Model_Data!A:A=$A8)*(Model_Data!B:B=TEXT(EDATE($B8,-12),"mmm-yy")),Model_Data!C:C)} -> 4432.19 | D8: {=_xlfn.XLOOKUP(1,(Model_Data!A:A=$A8)*(Model_Data!B:B=TEXT($B8,"mmm-yy")),Model_Data!C:C)} -> 4718.92 | E8: =D8-C8 -> 286.73 | F8: =E8/C8 -> 0.064692624 | G8: =IF(E8>0,"Favourable","Unfavourable") -> Favourable | J8: =B8 -> 46112 | K8: =IF(Dashboard!$L$10="Sales",C8,IF(Dashboard!$L$10="Expenses",C14,C20)) -> 3631.67 | L8: =IF(Dashboard!$L$10="Sales",D8,IF(Dashboard!$L$10="Expenses",D14,D20)) -> 3885.35 | M8: =MAX(K8,L8)+300 -> 4185.35 | N8: =L8/K8-1 -> 0.069852162
A9: =Quarters!$A$4 -> Sales | B9: 46203 | C9: {=_xlfn.XLOOKUP(1,(Model_Data!A:A=$A9)*(Model_Data!B:B=TEXT(EDATE($B9,-12),"mmm-yy")),Model_Data!C:C)} -> 4622.22 | D9: {=_xlfn.XLOOKUP(1,(Model_Data!A:A=$A9)*(Model_Data!B:B=TEXT($B9,"mmm-yy")),Model_Data!C:C)} -> 4999.97 | E9: =D9-C9 -> 377.75 | F9: =E9/C9 -> 0.081724799 | G9: =IF(E9>0,"Favourable","Unfavourable") -> Favourable | J9: =B9 -> 46203 | K9: =IF(Dashboard!$L$10="Sales",C9,IF(Dashboard!$L$10="Expenses",C15,C21)) -> 3870.02 | L9: =IF(Dashboard!$L$10="Sales",D9,IF(Dashboard!$L$10="Expenses",D15,D21)) -> 4161.65 | M9: =MAX(K9,L9)+300 -> 4461.65 | N9: =L9/K9-1 -> 0.0753562
A10: =Quarters!$A$5 -> Expenses | B10: {=TRANSPOSE(Quarters!F3:K3)} -> 45747 | C10: {=_xlfn.XLOOKUP(1,(Model_Data!A:A=$A10)*(Model_Data!B:B=TEXT(EDATE($B10,-12),"mmm-yy")),Model_Data!C:C)} -> 3285.71 | D10: {=_xlfn.XLOOKUP(1,(Model_Data!A:A=$A10)*(Model_Data!B:B=TEXT($B10,"mmm-yy")),Model_Data!C:C)} -> 3631.67 | E10: =D10-C10 -> 345.96 | F10: =E10/C10 -> 0.10529231 | G10: =IF(E10<0,"Favourable","Unfavourable") -> Unfavourable
A11: =Quarters!$A$5 -> Expenses | B11: 45838 | C11: {=_xlfn.XLOOKUP(1,(Model_Data!A:A=$A11)*(Model_Data!B:B=TEXT(EDATE($B11,-12),"mmm-yy")),Model_Data!C:C)} -> 3497.28 | D11: {=_xlfn.XLOOKUP(1,(Model_Data!A:A=$A11)*(Model_Data!B:B=TEXT($B11,"mmm-yy")),Model_Data!C:C)} -> 3870.02 | E11: =D11-C11 -> 372.74 | F11: =E11/C11 -> 0.10657997 | G11: =IF(E11<0,"Favourable","Unfavourable") -> Unfavourable
A12: =Quarters!$A$5 -> Expenses | B12: 45930 | C12: {=_xlfn.XLOOKUP(1,(Model_Data!A:A=$A12)*(Model_Data!B:B=TEXT(EDATE($B12,-12),"mmm-yy")),Model_Data!C:C)} -> 3887.56 | D12: {=_xlfn.XLOOKUP(1,(Model_Data!A:A=$A12)*(Model_Data!B:B=TEXT($B12,"mmm-yy")),Model_Data!C:C)} -> 3889.39 | E12: =D12-C12 -> 1.83 | F12: =E12/C12 -> 0.00047073228 | G12: =IF(E12<0,"Favourable","Unfavourable") -> Unfavourable
A13: =Quarters!$A$5 -> Expenses | B13: 46022 | C13: {=_xlfn.XLOOKUP(1,(Model_Data!A:A=$A13)*(Model_Data!B:B=TEXT(EDATE($B13,-12),"mmm-yy")),Model_Data!C:C)} -> 3749.75 | D13: {=_xlfn.XLOOKUP(1,(Model_Data!A:A=$A13)*(Model_Data!B:B=TEXT($B13,"mmm-yy")),Model_Data!C:C)} -> 3992.49 | E13: =D13-C13 -> 242.74 | F13: =E13/C13 -> 0.064734982 | G13: =IF(E13<0,"Favourable","Unfavourable") -> Unfavourable
A14: =Quarters!$A$5 -> Expenses | B14: 46112 | C14: {=_xlfn.XLOOKUP(1,(Model_Data!A:A=$A14)*(Model_Data!B:B=TEXT(EDATE($B14,-12),"mmm-yy")),Model_Data!C:C)} -> 3631.67 | D14: {=_xlfn.XLOOKUP(1,(Model_Data!A:A=$A14)*(Model_Data!B:B=TEXT($B14,"mmm-yy")),Model_Data!C:C)} -> 3885.35 | E14: =D14-C14 -> 253.68 | F14: =E14/C14 -> 0.069852162 | G14: =IF(E14<0,"Favourable","Unfavourable") -> Unfavourable
A15: =Quarters!$A$5 -> Expenses | B15: 46203 | C15: {=_xlfn.XLOOKUP(1,(Model_Data!A:A=$A15)*(Model_Data!B:B=TEXT(EDATE($B15,-12),"mmm-yy")),Model_Data!C:C)} -> 3870.02 | D15: {=_xlfn.XLOOKUP(1,(Model_Data!A:A=$A15)*(Model_Data!B:B=TEXT($B15,"mmm-yy")),Model_Data!C:C)} -> 4161.65 | E15: =D15-C15 -> 291.63 | F15: =E15/C15 -> 0.0753562 | G15: =IF(E15<0,"Favourable","Unfavourable") -> Unfavourable
A16: =Quarters!$A$6 -> Operating Profit | B16: {=TRANSPOSE(Quarters!F3:K3)} -> 45747 | C16: {=_xlfn.XLOOKUP(1,(Model_Data!A:A=$A16)*(Model_Data!B:B=TEXT(EDATE($B16,-12),"mmm-yy")),Model_Data!C:C)} -> 783.65 | D16: {=_xlfn.XLOOKUP(1,(Model_Data!A:A=$A16)*(Model_Data!B:B=TEXT($B16,"mmm-yy")),Model_Data!C:C)} -> 800.52 | E16: =D16-C16 -> 16.87 | F16: =E16/C16 -> 0.021527468 | G16: =IF(E16>0,"Favourable","Unfavourable") -> Favourable
A17: =Quarters!$A$6 -> Operating Profit | B17: 45838 | C17: {=_xlfn.XLOOKUP(1,(Model_Data!A:A=$A17)*(Model_Data!B:B=TEXT(EDATE($B17,-12),"mmm-yy")),Model_Data!C:C)} -> 753.01 | D17: {=_xlfn.XLOOKUP(1,(Model_Data!A:A=$A17)*(Model_Data!B:B=TEXT($B17,"mmm-yy")),Model_Data!C:C)} -> 752.2 | E17: =D17-C17 -> -0.81 | F17: =E17/C17 -> -0.0010756829 | G17: =IF(E17>0,"Favourable","Unfavourable") -> Unfavourable
A18: =Quarters!$A$6 -> Operating Profit | B18: 45930 | C18: {=_xlfn.XLOOKUP(1,(Model_Data!A:A=$A18)*(Model_Data!B:B=TEXT(EDATE($B18,-12),"mmm-yy")),Model_Data!C:C)} -> 780.01 | D18: {=_xlfn.XLOOKUP(1,(Model_Data!A:A=$A18)*(Model_Data!B:B=TEXT($B18,"mmm-yy")),Model_Data!C:C)} -> 951.24 | E18: =D18-C18 -> 171.23 | F18: =E18/C18 -> 0.21952283 | G18: =IF(E18>0,"Favourable","Unfavourable") -> Favourable
A19: =Quarters!$A$6 -> Operating Profit | B19: 46022 | C19: {=_xlfn.XLOOKUP(1,(Model_Data!A:A=$A19)*(Model_Data!B:B=TEXT(EDATE($B19,-12),"mmm-yy")),Model_Data!C:C)} -> 842.86 | D19: {=_xlfn.XLOOKUP(1,(Model_Data!A:A=$A19)*(Model_Data!B:B=TEXT($B19,"mmm-yy")),Model_Data!C:C)} -> 977.33 | E19: =D19-C19 -> 134.47 | F19: =E19/C19 -> 0.15954014 | G19: =IF(E19>0,"Favourable","Unfavourable") -> Favourable
A20: =Quarters!$A$6 -> Operating Profit | B20: 46112 | C20: {=_xlfn.XLOOKUP(1,(Model_Data!A:A=$A20)*(Model_Data!B:B=TEXT(EDATE($B20,-12),"mmm-yy")),Model_Data!C:C)} -> 800.52 | D20: {=_xlfn.XLOOKUP(1,(Model_Data!A:A=$A20)*(Model_Data!B:B=TEXT($B20,"mmm-yy")),Model_Data!C:C)} -> 833.57 | E20: =D20-C20 -> 33.05 | F20: =E20/C20 -> 0.041285664 | G20: =IF(E20>0,"Favourable","Unfavourable") -> Favourable
A21: =Quarters!$A$6 -> Operating Profit | B21: 46203 | C21: {=_xlfn.XLOOKUP(1,(Model_Data!A:A=$A21)*(Model_Data!B:B=TEXT(EDATE($B21,-12),"mmm-yy")),Model_Data!C:C)} -> 752.2 | D21: {=_xlfn.XLOOKUP(1,(Model_Data!A:A=$A21)*(Model_Data!B:B=TEXT($B21,"mmm-yy")),Model_Data!C:C)} -> 838.32 | E21: =D21-C21 -> 86.12 | F21: =E21/C21 -> 0.11449083 | G21: =IF(E21>0,"Favourable","Unfavourable") -> Favourable

Sheet Forecast
A1: FORECAST | C1: Sales | E1: Avg Growth ( rolling last 4 Qtr) | F1: Next Qtr Forecast | H1: Best Case ( Annual ) | I1: Worst case ( Annual ) | K1: Quarter | L1: Actual | M1: 4-QTR Forecast
A2: Sales | E2: {=_xlfn.IFS(C1="Sales",AVERAGE(OFFSET(C13,-3,0,4,1)),C1="Expenses",AVERAGE(OFFSET(C27,-3,0,4,1)),C1="Operating Profit",AVERAGE(OFFSET(C40,-3,0,4,1)))} -> 0.020753564 | F2: {=_xlfn.IFS(C1="Sales",B13*(1+E2),C1="Expenses",B27*(1+E2),C1="Operating Profit",B40*(1+E2))} -> 5103.7372 | H2: {=_xlfn.IFS(C1="Sales",'Profit & Loss'!M4,C1="Expenses",'Profit & Loss'!M5,C1="Operating Profit",'Profit & Loss'!M6)} -> 20441.963 | I2: {=_xlfn.IFS(C1="Sales",'Profit & Loss'!N4,C1="Expenses",'Profit & Loss'!N5,C1="Operating Profit",'Profit & Loss'!N6)} -> 20229.582 | K2: ="Q" & ROUND(MONTH(A10)/3,0) & " FY"&YEAR(A10) -> Q3 FY2025 | L2: =B10 -> 4840.63
A3: Quarter | B3: Actual | C3: Growth % | K3: ="Q" & ROUND(MONTH(A11)/3,0) & " FY"&YEAR(A11) -> Q4 FY2025 | L3: =B11 -> 4969.82
A4: {=TRANSPOSE(Quarters!B3:K3)} -> 45382 | B4: {=_xlfn.XLOOKUP(1,(Model_Data!A:A="Sales")*(Model_Data!B:B=TEXT($A4,"mmm-yy")),Model_Data!C:C)} -> 4069.36 | K4: ="Q" & ROUND(MONTH(A12)/3,0) & " FY"&YEAR(A12) -> Q1 FY2026 | L4: =B12 -> 4718.92
A5: 45473 | B5: {=_xlfn.XLOOKUP(1,(Model_Data!A:A="Sales")*(Model_Data!B:B=TEXT($A5,"mmm-yy")),Model_Data!C:C)} -> 4250.29 | C5: =(B5-B4)/B4 -> 0.044461537 | K5: ="Q" & ROUND(MONTH(A13)/3,0) & " FY"&YEAR(A13) -> Q2 FY2026 | L5: =B13 -> 4999.97 | M5: =L5 -> 4999.97
A6: 45565 | B6: {=_xlfn.XLOOKUP(1,(Model_Data!A:A="Sales")*(Model_Data!B:B=TEXT($A6,"mmm-yy")),Model_Data!C:C)} -> 4667.57 | C6: =(B6-B5)/B5 -> 0.09817683 | K6: Q3 FY2026 | M6: =L5*(1+$E$2) -> 5103.7372
A7: 45657 | B7: {=_xlfn.XLOOKUP(1,(Model_Data!A:A="Sales")*(Model_Data!B:B=TEXT($A7,"mmm-yy")),Model_Data!C:C)} -> 4592.61 | C7: =(B7-B6)/B6 -> -0.016059748 | K7: Q4 FY2026 | M7: =M6*(1+$E$2) -> 5209.6579
A8: 45747 | B8: {=_xlfn.XLOOKUP(1,(Model_Data!A:A="Sales")*(Model_Data!B:B=TEXT($A8,"mmm-yy")),Model_Data!C:C)} -> 4432.19 | C8: =(B8-B7)/B7 -> -0.034930029 | K8: Q1 FY2027 | M8: =M7*(1+$E$2) -> 5317.7769
A9: 45838 | B9: {=_xlfn.XLOOKUP(1,(Model_Data!A:A="Sales")*(Model_Data!B:B=TEXT($A9,"mmm-yy")),Model_Data!C:C)} -> 4622.22 | C9: =(B9-B8)/B8 -> 0.042874967 | K9: Q2 FY2027 | M9: =M8*(1+$E$2) -> 5428.1397
A10: 45930 | B10: {=_xlfn.XLOOKUP(1,(Model_Data!A:A="Sales")*(Model_Data!B:B=TEXT($A10,"mmm-yy")),Model_Data!C:C)} -> 4840.63 | C10: =(B10-B9)/B9 -> 0.047252186
A11: 46022 | B11: {=_xlfn.XLOOKUP(1,(Model_Data!A:A="Sales")*(Model_Data!B:B=TEXT($A11,"mmm-yy")),Model_Data!C:C)} -> 4969.82 | C11: =(B11-B10)/B10 -> 0.026688675
A12: 46112 | B12: {=_xlfn.XLOOKUP(1,(Model_Data!A:A="Sales")*(Model_Data!B:B=TEXT($A12,"mmm-yy")),Model_Data!C:C)} -> 4718.92 | C12: =(B12-B11)/B11 -> -0.050484726
A13: 46203 | B13: {=_xlfn.XLOOKUP(1,(Model_Data!A:A="Sales")*(Model_Data!B:B=TEXT($A13,"mmm-yy")),Model_Data!C:C)} -> 4999.97 | C13: =(B13-B12)/B12 -> 0.059558119
A16: Expenses
A17: Quarter | B17: Actual | C17: Growth %
A18: {=TRANSPOSE(Quarters!B3:K3)} -> 45382 | B18: {=_xlfn.XLOOKUP(1,(Model_Data!A:A="Expenses")*(Model_Data!B:B=TEXT($A18,"mmm-yy")),Model_Data!C:C)} -> 3285.71
A19: 45473 | B19: {=_xlfn.XLOOKUP(1,(Model_Data!A:A="Expenses")*(Model_Data!B:B=TEXT($A19,"mmm-yy")),Model_Data!C:C)} -> 3497.28 | C19: =(B19-B18)/B18 -> 0.064390954
A20: 45565 | B20: {=_xlfn.XLOOKUP(1,(Model_Data!A:A="Expenses")*(Model_Data!B:B=TEXT($A20,"mmm-yy")),Model_Data!C:C)} -> 3887.56 | C20: =(B20-B19)/B19 -> 0.1115953
A21: 45657 | B21: {=_xlfn.XLOOKUP(1,(Model_Data!A:A="Expenses")*(Model_Data!B:B=TEXT($A21,"mmm-yy")),Model_Data!C:C)} -> 3749.75 | C21: =(B21-B20)/B20 -> -0.035448971
A22: 45747 | B22: {=_xlfn.XLOOKUP(1,(Model_Data!A:A="Expenses")*(Model_Data!B:B=TEXT($A22,"mmm-yy")),Model_Data!C:C)} -> 3631.67 | C22: =(B22-B21)/B21 -> -0.031490099
A23: 45838 | B23: {=_xlfn.XLOOKUP(1,(Model_Data!A:A="Expenses")*(Model_Data!B:B=TEXT($A23,"mmm-yy")),Model_Data!C:C)} -> 3870.02 | C23: =(B23-B22)/B22 -> 0.065630963
A24: 45930 | B24: {=_xlfn.XLOOKUP(1,(Model_Data!A:A="Expenses")*(Model_Data!B:B=TEXT($A24,"mmm-yy")),Model_Data!C:C)} -> 3889.39 | C24: =(B24-B23)/B23 -> 0.0050051421
A25: 46022 | B25: {=_xlfn.XLOOKUP(1,(Model_Data!A:A="Expenses")*(Model_Data!B:B=TEXT($A25,"mmm-yy")),Model_Data!C:C)} -> 3992.49 | C25: =(B25-B24)/B24 -> 0.026508013
A26: 46112 | B26: {=_xlfn.XLOOKUP(1,(Model_Data!A:A="Expenses")*(Model_Data!B:B=TEXT($A26,"mmm-yy")),Model_Data!C:C)} -> 3885.35 | C26: =(B26-B25)/B25 -> -0.026835383
A27: 46203 | B27: {=_xlfn.XLOOKUP(1,(Model_Data!A:A="Expenses")*(Model_Data!B:B=TEXT($A27,"mmm-yy")),Model_Data!C:C)} -> 4161.65 | C27: =(B27-B26)/B26 -> 0.071113285
A29: Operating Profit
A30: Quarter | B30: Actual | C30: Growth %
A31: {=TRANSPOSE(Quarters!B3:K3)} -> 45382 | B31: {=_xlfn.XLOOKUP(1,(Model_Data!A:A="Operating Profit")*(Model_Data!B:B=TEXT($A31,"mmm-yy")),Model_Data!C:C)} -> 783.65
A32: 45473 | B32: {=_xlfn.XLOOKUP(1,(Model_Data!A:A="Operating Profit")*(Model_Data!B:B=TEXT($A32,"mmm-yy")),Model_Data!C:C)} -> 753.01 | C32: =(B32-B31)/B31 -> -0.039099088
A33: 45565 | B33: {=_xlfn.XLOOKUP(1,(Model_Data!A:A="Operating Profit")*(Model_Data!B:B=TEXT($A33,"mmm-yy")),Model_Data!C:C)} -> 780.01 | C33: =(B33-B32)/B32 -> 0.035856098
A34: 45657 | B34: {=_xlfn.XLOOKUP(1,(Model_Data!A:A="Operating Profit")*(Model_Data!B:B=TEXT($A34,"mmm-yy")),Model_Data!C:C)} -> 842.86 | C34: =(B34-B33)/B33 -> 0.08057589
A35: 45747 | B35: {=_xlfn.XLOOKUP(1,(Model_Data!A:A="Operating Profit")*(Model_Data!B:B=TEXT($A35,"mmm-yy")),Model_Data!C:C)} -> 800.52 | C35: =(B35-B34)/B34 -> -0.050233728
A36: 45838 | B36: {=_xlfn.XLOOKUP(1,(Model_Data!A:A="Operating Profit")*(Model_Data!B:B=TEXT($A36,"mmm-yy")),Model_Data!C:C)} -> 752.2 | C36: =(B36-B35)/B35 -> -0.060360766
A37: 45930 | B37: {=_xlfn.XLOOKUP(1,(Model_Data!A:A="Operating Profit")*(Model_Data!B:B=TEXT($A37,"mmm-yy")),Model_Data!C:C)} -> 951.24 | C37: =(B37-B36)/B36 -> 0.26461048
A38: 46022 | B38: {=_xlfn.XLOOKUP(1,(Model_Data!A:A="Operating Profit")*(Model_Data!B:B=TEXT($A38,"mmm-yy")),Model_Data!C:C)} -> 977.33 | C38: =(B38-B37)/B37 -> 0.027427358
A39: 46112 | B39: {=_xlfn.XLOOKUP(1,(Model_Data!A:A="Operating Profit")*(Model_Data!B:B=TEXT($A39,"mmm-yy")),Model_Data!C:C)} -> 833.57 | C39: =(B39-B38)/B38 -> -0.14709464
A40: 46203 | B40: {=_xlfn.XLOOKUP(1,(Model_Data!A:A="Operating Profit")*(Model_Data!B:B=TEXT($A40,"mmm-yy")),Model_Data!C:C)} -> 838.32 | C40: =(B40-B39)/B39 -> 0.0056983817

Sheet Balance Sheet
A1: ='Profit & Loss'!A1 -> BRITANNIA INDUSTRIES LTD | E1: =UPDATE | J1: SCREENER.IN
A3: Narration | B3: ='Data Sheet'!B56 -> 42825 | C3: ='Data Sheet'!C56 -> 43190 | D3: ='Data Sheet'!D56 -> 43555 | E3: ='Data Sheet'!E56 -> 43921 | F3: ='Data Sheet'!F56 -> 44286 | G3: ='Data Sheet'!G56 -> 44651 | H3: ='Data Sheet'!H56 -> 45016 | I3: ='Data Sheet'!I56 -> 45382 | ... K3: ='Data Sheet'!K56 -> 46112
A4: Equity Share Capital | B4: ='Data Sheet'!B57 -> 24 | C4: ='Data Sheet'!C57 -> 24.01 | D4: ='Data Sheet'!D57 -> 24.03 | E4: ='Data Sheet'!E57 -> 24.05 | F4: ='Data Sheet'!F57 -> 24.09 | G4: ='Data Sheet'!G57 -> 24.09 | H4: ='Data Sheet'!H57 -> 24.09 | I4: ='Data Sheet'!I57 -> 24.09 | ... K4: ='Data Sheet'!K57 -> 24.09
A5: Reserves | B5: ='Data Sheet'!B58 -> 2672.42 | C5: ='Data Sheet'!C58 -> 3382.22 | D5: ='Data Sheet'!D58 -> 4229.22 | E5: ='Data Sheet'!E58 -> 4378.78 | F5: ='Data Sheet'!F58 -> 3523.57 | G5: ='Data Sheet'!G58 -> 2534.01 | H5: ='Data Sheet'!H58 -> 3510.18 | I5: ='Data Sheet'!I58 -> 3917.43 | ... K5: ='Data Sheet'!K58 -> 5082.47
A6: Borrowings | B6: ='Data Sheet'!B59 -> 124.56 | C6: ='Data Sheet'!C59 -> 200.7 | D6: ='Data Sheet'!D59 -> 156.02 | E6: ='Data Sheet'!E59 -> 1537.59 | F6: ='Data Sheet'!F59 -> 2106.94 | G6: ='Data Sheet'!G59 -> 2481.2 | H6: ='Data Sheet'!H59 -> 2997.37 | I6: ='Data Sheet'!I59 -> 2064.96 | ... K6: ='Data Sheet'!K59 -> 1380.28
A7: Other Liabilities | B7: ='Data Sheet'!B60 -> 1287.82 | C7: ='Data Sheet'!C60 -> 1580.99 | D7: ='Data Sheet'!D60 -> 1828.68 | E7: ='Data Sheet'!E60 -> 1889.12 | F7: ='Data Sheet'!F60 -> 2345.49 | G7: ='Data Sheet'!G60 -> 2487.3 | H7: ='Data Sheet'!H60 -> 2819.21 | I7: ='Data Sheet'!I60 -> 3065.02 | ... K7: ='Data Sheet'!K60 -> 3243.48
A8: Total | B8: ='Data Sheet'!B61 -> 4108.8 | C8: ='Data Sheet'!C61 -> 5187.92 | D8: ='Data Sheet'!D61 -> 6237.95 | E8: ='Data Sheet'!E61 -> 7829.54 | F8: ='Data Sheet'!F61 -> 8000.09 | G8: ='Data Sheet'!G61 -> 7526.6 | H8: ='Data Sheet'!H61 -> 9350.85 | I8: ='Data Sheet'!I61 -> 9071.5 | ... K8: ='Data Sheet'!K61 -> 9730.32
A10: Net Block | B10: ='Data Sheet'!B62 -> 1159.99 | C10: ='Data Sheet'!C62 -> 1345.6 | D10: ='Data Sheet'!D62 -> 1688.3 | E10: ='Data Sheet'!E62 -> 1878.18 | F10: ='Data Sheet'!F62 -> 1792.95 | G10: ='Data Sheet'!G62 -> 1753.21 | H10: ='Data Sheet'!H62 -> 2655.22 | I10: ='Data Sheet'!I62 -> 2771.14 | ... K10: ='Data Sheet'!K62 -> 2849.92
A11: Capital Work in Progress | B11: ='Data Sheet'!B63 -> 30.07 | C11: ='Data Sheet'!C63 -> 202.82 | D11: ='Data Sheet'!D63 -> 101.24 | E11: ='Data Sheet'!E63 -> 39.55 | F11: ='Data Sheet'!F63 -> 116.52 | G11: ='Data Sheet'!G63 -> 535.68 | H11: ='Data Sheet'!H63 -> 105 | I11: ='Data Sheet'!I63 -> 187.54 | ... K11: ='Data Sheet'!K63 -> 39.04
A12: Investments | B12: ='Data Sheet'!B64 -> 486.85 | C12: ='Data Sheet'!C64 -> 1079.28 | D12: ='Data Sheet'!D64 -> 1476.28 | E12: ='Data Sheet'!E64 -> 2893.23 | F12: ='Data Sheet'!F64 -> 2780.69 | G12: ='Data Sheet'!G64 -> 1762.37 | H12: ='Data Sheet'!H64 -> 3324.24 | I12: ='Data Sheet'!I64 -> 2766.72 | ... K12: ='Data Sheet'!K64 -> 3609.76
A13: Other Assets | B13: ='Data Sheet'!B65 -> 2431.89 | C13: ='Data Sheet'!C65 -> 2560.22 | D13: ='Data Sheet'!D65 -> 2972.13 | E13: ='Data Sheet'!E65 -> 3018.58 | F13: ='Data Sheet'!F65 -> 3309.93 | G13: ='Data Sheet'!G65 -> 3475.34 | H13: ='Data Sheet'!H65 -> 3266.39 | I13: ='Data Sheet'!I65 -> 3346.1 | ... K13: ='Data Sheet'!K65 -> 3231.6
A14: Total | B14: ='Data Sheet'!B66 -> 4108.8 | C14: ='Data Sheet'!C66 -> 5187.92 | D14: ='Data Sheet'!D66 -> 6237.95 | E14: ='Data Sheet'!E66 -> 7829.54 | F14: ='Data Sheet'!F66 -> 8000.09 | G14: ='Data Sheet'!G66 -> 7526.6 | H14: ='Data Sheet'!H66 -> 9350.85 | I14: ='Data Sheet'!I66 -> 9071.5 | ... K14: ='Data Sheet'!K66 -> 9730.32
A16: Working Capital | B16: =B13-B7 -> 1144.07 | C16: =C13-C7 -> 979.23 | D16: =D13-D7 -> 1143.45 | E16: =E13-E7 -> 1129.46 | F16: =F13-F7 -> 964.44 | G16: =G13-G7 -> 988.04 | H16: =H13-H7 -> 447.18 | I16: =I13-I7 -> 281.08 | ... K16: =K13-K7 -> -11.88
A17: Debtors | B17: ='Data Sheet'!B67 -> 179.16 | C17: ='Data Sheet'!C67 -> 304.6 | D17: ='Data Sheet'!D67 -> 394.24 | E17: ='Data Sheet'!E67 -> 320.36 | F17: ='Data Sheet'!F67 -> 257.27 | G17: ='Data Sheet'!G67 -> 331.93 | H17: ='Data Sheet'!H67 -> 328.94 | I17: ='Data Sheet'!I67 -> 393.33 | ... K17: ='Data Sheet'!K67 -> 469.21
A18: Inventory | B18: ='Data Sheet'!B68 -> 661.45 | C18: ='Data Sheet'!C68 -> 652.79 | D18: ='Data Sheet'!D68 -> 781.38 | E18: ='Data Sheet'!E68 -> 740.96 | F18: ='Data Sheet'!F68 -> 1091.49 | G18: ='Data Sheet'!G68 -> 1367.49 | H18: ='Data Sheet'!H68 -> 1193.26 | I18: ='Data Sheet'!I68 -> 1181.22 | ... K18: ='Data Sheet'!K68 -> 1345.93
A20: Debtor Days | B20: =IF('Profit & Loss'!B4>0,'Balance Sheet'!B17/('Profit & Loss'!B4/365),0) -> 7.222526 | C20: =IF('Profit & Loss'!C4>0,'Balance Sheet'!C17/('Profit & Loss'!C4/365),0) -> 11.214355 | D20: =IF('Profit & Loss'!D4>0,'Balance Sheet'!D17/('Profit & Loss'!D4/365),0) -> 13.016906 | E20: =IF('Profit & Loss'!E4>0,'Balance Sheet'!E17/('Profit & Loss'!E4/365),0) -> 10.080684 | F20: =IF('Profit & Loss'!F4>0,'Balance Sheet'!F17/('Profit & Loss'!F4/365),0) -> 7.1484888 | G20: =IF('Profit & Loss'!G4>0,'Balance Sheet'!G17/('Profit & Loss'!G4/365),0) -> 8.5704741 | H20: =IF('Profit & Loss'!H4>0,'Balance Sheet'!H17/('Profit & Loss'!H4/365),0) -> 7.3655858 | I20: =IF('Profit & Loss'!I4>0,'Balance Sheet'!I17/('Profit & Loss'!I4/365),0) -> 8.5612224 | ... K20: =IF('Profit & Loss'!K4>0,'Balance Sheet'!K17/('Profit & Loss'!K4/365),0) -> 8.9424246
A21: Inventory Turnover | B21: =IF('Balance Sheet'!B18>0,'Profit & Loss'!B4/'Balance Sheet'!B18,0) -> 13.688246 | C21: =IF('Balance Sheet'!C18>0,'Profit & Loss'!C4/'Balance Sheet'!C18,0) -> 15.187105 | D21: =IF('Balance Sheet'!D18>0,'Profit & Loss'!D4/'Balance Sheet'!D18,0) -> 14.147623 | E21: =IF('Balance Sheet'!E18>0,'Profit & Loss'!E4/'Balance Sheet'!E18,0) -> 15.654759 | F21: =IF('Balance Sheet'!F18>0,'Profit & Loss'!F4/'Balance Sheet'!F18,0) -> 12.035053 | G21: =IF('Balance Sheet'!G18>0,'Profit & Loss'!G4/'Balance Sheet'!G18,0) -> 10.337377 | H21: =IF('Balance Sheet'!H18>0,'Profit & Loss'!H4/'Balance Sheet'!H18,0) -> 13.660518 | I21: =IF('Balance Sheet'!I18>0,'Profit & Loss'!I4/'Balance Sheet'!I18,0) -> 14.196568 | ... K21: =IF('Balance Sheet'!K18>0,'Profit & Loss'!K4/'Balance Sheet'!K18,0) -> 14.229262
A23: Return on Equity | B23: =IF(SUM('Balance Sheet'!B4:B5)>0,'Profit & Loss'!B12/SUM('Balance Sheet'!B4:B5),"") -> 0.32801641 | C23: =IF(SUM('Balance Sheet'!C4:C5)>0,'Profit & Loss'!C12/SUM('Balance Sheet'!C4:C5),"") -> 0.29482155 | D23: =IF(SUM('Balance Sheet'!D4:D5)>0,'Profit & Loss'!D12/SUM('Balance Sheet'!D4:D5),"") -> 0.27252572 | E23: =IF(SUM('Balance Sheet'!E4:E5)>0,'Profit & Loss'!E12/SUM('Balance Sheet'!E4:E5),"") -> 0.31857464 | F23: =IF(SUM('Balance Sheet'!F4:F5)>0,'Profit & Loss'!F12/SUM('Balance Sheet'!F4:F5),"") -> 0.52538857 | G23: =IF(SUM('Balance Sheet'!G4:G5)>0,'Profit & Loss'!G12/SUM('Balance Sheet'!G4:G5),"") -> 0.59607521 | H23: =IF(SUM('Balance Sheet'!H4:H5)>0,'Profit & Loss'!H12/SUM('Balance Sheet'!H4:H5),"") -> 0.65693057 | I23: =IF(SUM('Balance Sheet'!I4:I5)>0,'Profit & Loss'!I12/SUM('Balance Sheet'!I4:I5),"") -> 0.54288955 | ... K23: =IF(SUM('Balance Sheet'!K4:K5)>0,'Profit & Loss'!K12/SUM('Balance Sheet'!K4:K5),"") -> 0.49612459
A24: Return on Capital Emp | C24: =IF((B4+B5+B6+C4+C5+C6)>0,('Profit & Loss'!C10+'Profit & Loss'!C9)*2/(B4+B5+B6+C4+C5+C6),"") -> 0.47473284 | D24: =IF((C4+C5+C6+D4+D5+D6)>0,('Profit & Loss'!D10+'Profit & Loss'!D9)*2/(C4+C5+C6+D4+D5+D6),"") -> 0.4433572 | E24: =IF((D4+D5+D6+E4+E5+E6)>0,('Profit & Loss'!E10+'Profit & Loss'!E9)*2/(D4+D5+D6+E4+E5+E6),"") -> 0.3712575 | F24: =IF((E4+E5+E6+F4+F5+F6)>0,('Profit & Loss'!F10+'Profit & Loss'!F9)*2/(E4+E5+E6+F4+F5+F6),"") -> 0.45269607 | G24: =IF((F4+F5+F6+G4+G5+G6)>0,('Profit & Loss'!G10+'Profit & Loss'!G9)*2/(F4+F5+F6+G4+G5+G6),"") -> 0.41567997 | H24: =IF((G4+G5+G6+H4+H5+H6)>0,('Profit & Loss'!H10+'Profit & Loss'!H9)*2/(G4+G5+G6+H4+H5+H6),"") -> 0.553433 | I24: =IF((H4+H5+H6+I4+I5+I6)>0,('Profit & Loss'!I10+'Profit & Loss'!I9)*2/(H4+H5+H6+I4+I5+I6),"") -> 0.49089816 | J24: =IF((I4+I5+I6+J4+J5+J6)>0,('Profit & Loss'!J10+'Profit & Loss'!J9)*2/(I4+I5+I6+J4+J5+J6),"") -> 0.52811553 | K24: =IF((J4+J5+J6+K4+K5+K6)>0,('Profit & Loss'!K10+'Profit & Loss'!K9)*2/(J4+J5+J6+K4+K5+K6),"") -> 0.56274635

Sheet Cash Flow
A1: ='Balance Sheet'!A1 -> BRITANNIA INDUSTRIES LTD | E1: =UPDATE | J1: SCREENER.IN
A3: Narration | B3: ='Data Sheet'!B81 -> 42825 | C3: ='Data Sheet'!C81 -> 43190 | D3: ='Data Sheet'!D81 -> 43555 | E3: ='Data Sheet'!E81 -> 43921 | F3: ='Data Sheet'!F81 -> 44286 | G3: ='Data Sheet'!G81 -> 44651 | H3: ='Data Sheet'!H81 -> 45016 | I3: ='Data Sheet'!I81 -> 45382 | ... K3: ='Data Sheet'!K81 -> 46112
A4: Cash from Operating Activity | B4: ='Data Sheet'!B82 -> 441.28 | C4: ='Data Sheet'!C82 -> 1248.77 | D4: ='Data Sheet'!D82 -> 1155.78 | E4: ='Data Sheet'!E82 -> 1484.53 | F4: ='Data Sheet'!F82 -> 1851.07 | G4: ='Data Sheet'!G82 -> 1299.52 | H4: ='Data Sheet'!H82 -> 2526.21 | I4: ='Data Sheet'!I82 -> 2572.98 | ... K4: ='Data Sheet'!K82 -> 2611.6
A5: Cash from Investing Activity | B5: ='Data Sheet'!B83 -> -149.85 | C5: ='Data Sheet'!C83 -> -956.52 | D5: ='Data Sheet'!D83 -> -852.22 | E5: ='Data Sheet'!E83 -> -1525.93 | F5: ='Data Sheet'!F83 -> 458.82 | G5: ='Data Sheet'!G83 -> 914.19 | H5: ='Data Sheet'!H83 -> -1507 | I5: ='Data Sheet'!I83 -> 485.44 | ... K5: ='Data Sheet'!K83 -> -741.38
A6: Cash from Financing Activity | B6: ='Data Sheet'!B84 -> -295.08 | C6: ='Data Sheet'!C84 -> -231.75 | D6: ='Data Sheet'!D84 -> -352.68 | E6: ='Data Sheet'!E84 -> 57.94 | F6: ='Data Sheet'!F84 -> -2243.69 | G6: ='Data Sheet'!G84 -> -2245.84 | H6: ='Data Sheet'!H84 -> -1028.37 | I6: ='Data Sheet'!I84 -> -2839.13 | ... K6: ='Data Sheet'!K84 -> -1782.62
A7: Net Cash Flow | B7: ='Data Sheet'!B85 -> -3.65 | C7: ='Data Sheet'!C85 -> 60.5 | D7: ='Data Sheet'!D85 -> -49.12 | E7: ='Data Sheet'!E85 -> 16.54 | F7: ='Data Sheet'!F85 -> 66.2 | G7: ='Data Sheet'!G85 -> -32.13 | H7: ='Data Sheet'!H85 -> -9.16 | I7: ='Data Sheet'!I85 -> 219.29 | ... K7: ='Data Sheet'!K85 -> 87.6

Sheet Customization
A1: How to use it?
A3: You can customize this workbook as you want.
B4: You can add custom formating, add conditional formating, add your own formulas… do ANYTHING.
B5: Please don't edit the "Data Sheet" only.
A7: After customization, you can upload this back on Screener.
B8: Upload on: | C8: https://www.screener.in/excel/
A10: Download your customized workbooks now onwards.
B11: Now whenever you will "Export to excel" from Screener, it will export your customized file.
A14: TESTING:
B15: This is a testing feature currently.
B16: You can report any formula errors on the worksheet at: support@screener.in
